Workbook
Name avger: Analysis!$E$14
Name billing: '[1]pivot tables'!$A$40
Name patient: '[1]pivot tables'!$A$5
Name Salary: Analysis!$E$10
Name Slicer_Department_Name: #N/A
Name Slicer_Employment_status: #N/A
Name Slicer_Hire_Date: #N/A
Name Slicer_Performance_Band: #N/A
Name Slicer_Salary: #N/A

Sheet Analysis Chart

Sheet Analysis
B1: SALARY ANALYSIS
A2: Headcount By Salary | E2: Total Employees | G2: Sum of salary by department
A3: Row Labels | B3: Count of Employees ID | C3: Average of Salary | E3: Count of Employees ID | G3: Row Labels | H3: Sum of Salary
A4: Finance | B4: 13 | C4: 86846.154 | E4: 117 | G4: Information Technology | H4: 2215429
A5: Human Resources | B5: 17 | C5: 85649.941 | G5: Operations | H5: 1929079
A6: Information Technology | B6: 28 | C6: 79122.464 | G6: Sales | H6: 1734909
A7: Marketing | B7: 15 | C7: 84737.733 | G7: Human Resources | H7: 1456049
A8: Operations | B8: 24 | C8: 80378.292 | E8: Total Payroll | G8: Marketing | H8: 1271066
A9: Sales | B9: 20 | C9: 86745.45 | E9: Sum of Salary | G9: Finance | H9: 1129000
A10: Grand Total | B10: 117 | C10: 83209.675 | E10: 9735532 | G10: Grand Total | H10: 9735532
E12: Average Salary
A13: Salary Distribution by performance band | E13: Average of Salary
A14: Row Labels | B14: Sum of Salary | E14: 83209.675
A15: Achieving | B15: 2784180 | D15: Average Salary Paid Per Department
A16: Developing | B16: 2529992 | D16: Row Labels | E16: Average of Salary
A17: Needs Improvement | B17: 2093458 | D17: Finance | E17: 86846.154
A18: Exceeding | B18: 1641410 | D18: Sales | E18: 86745.45
A19: Outstanding | B19: 686492 | D19: Human Resources | E19: 85649.941
A20: Grand Total | B20: 9735532 | D20: Marketing | E20: 84737.733
D21: Operations | E21: 80378.292
D22: Information Technology | E22: 79122.464
D23: Grand Total | E23: 83209.675
C26: Bonus Analysis
A27: Attirition Rate by Department | F27: Sum of Eligible Bonus Amount by Performance Band
A28: Count of Employees ID | B28: Column Labels | F28: Row Labels | G28: Sum of Eligible Bonus Amount
A29: Row Labels | B29: Active | C29: Left | D29: Resigned | E29: Grand Total | F29: Achieving | G29: 1.75
A30: Finance | B30: 1 | C30: 0 | D30: 0 | E30: 1 | F30: Developing | G30: 0.58
A31: Human Resources | B31: 1 | C31: 0 | D31: 0 | E31: 1 | F31: Exceeding | G31: 1.6
A32: Information Technology | B32: 0.6 | C32: 0.4 | D32: 0 | E32: 1 | F32: Needs Improvement | G32: 0
A33: Marketing | B33: 0.66666667 | C33: 0.33333333 | D33: 0 | E33: 1 | F33: Outstanding | G33: 1.08
A34: Operations | B34: 0.8 | C34: 0 | D34: 0.2 | E34: 1 | F34: Grand Total | G34: 5.01
A35: Sales | B35: 1 | C35: 0 | D35: 0 | E35: 1
A36: Grand Total | B36: 0.83333333 | C36: 0.125 | D36: 0.041666667 | E36: 1
A38: Total Bonus | D38: Average Bonus by Department
A39: Count of Employees ID | B39: Sum of Eligible Bonus Amount | D39: Row Labels | E39: Average of Eligible Bonus Amount
A40: 117 | B40: 5.01 | D40: Finance | E40: 0.037692308
D41: Human Resources | E41: 0.054705882
A42: Total Bonus by Department | D42: Information Technology | E42: 0.0375
A43: Row Labels | B43: Sum of Eligible Bonus Amount | D43: Marketing | E43: 0.046666667
A44: Finance | B44: 0.49 | D44: Operations | E44: 0.045416667
...

Sheet Dashboard

Sheet Raw_Employee_Data (2)
A1: Emp ID | B1: First Name | C1: Last Name | D1: Dept Code | E1: Salary | F1: Perf Score | G1: Employment Status | L1: Employees ID | M1: First Name | N1: Last Name | O1: Full Name | P1: Department code | Q1: Hire Date | R1: Performance Score | S1: Salary | T1: Employment status | U1: Department Name | V1: Performance Band | W1: Eligible Bonus Amount | X1: Year of service
A2: EMP127 | B2: Emily | C2: Brown | D2: IT02 | E2: 50361 | F2: 52 | G2: active | L2: =TRIM(A2) -> EMP127 | M2: =TRIM(PROPER(B2)) -> Emily | N2: =TRIM(PROPER(C2)) -> Brown | O2: Emily Brown | P2: =TRIM(UPPER(D2)) -> IT02 | Q2: 43093 | R2: 52 | S2: 50361 | T2: =TRIM(PROPER(G2)) -> Active | U2: =_xlfn.XLOOKUP(P2, Lookup_Departments!$A$2:$A$7, Lookup_Departments!$B$2:$B$7, "invalid code") -> Information Technology | V2: =_xlfn.XLOOKUP(R2, Lookup_Performance!$A$2:$A$6, Lookup_Performance!$C$2:$C$6, "not found", -1) -> Developing | W2: =_xlfn.XLOOKUP(R2, Lookup_Performance!$A$2:$A$6, Lookup_Performance!$D$2:$D$6, 0,-1) -> 0.02 | X2: =DATEDIF(Q2, TODAY(), "y") & " years " & DATEDIF(Q2, TODAY(), "ym") & "months" -> 8 years 6months
A3: EMP134 | B3: Emily | C3: Gonzalez | D3: IT02 | E3: 114425 | F3: 54 | G3: LEFT | L3: =TRIM(A3) -> EMP134 | M3: =TRIM(PROPER(B3)) -> Emily | N3: =TRIM(PROPER(C3)) -> Gonzalez | O3: Emily Gonzalez | P3: =TRIM(UPPER(D3)) -> IT02 | Q3: 42403 | R3: 54 | S3: 114425 | T3: =TRIM(PROPER(G3)) -> Left | U3: =_xlfn.XLOOKUP(P3, Lookup_Departments!$A$2:$A$7, Lookup_Departments!$B$2:$B$7, "invalid code") -> Information Technology | V3: =_xlfn.XLOOKUP(R3, Lookup_Performance!$A$2:$A$6, Lookup_Performance!$C$2:$C$6, "not found", -1) -> Developing | W3: =_xlfn.XLOOKUP(R3, Lookup_Performance!$A$2:$A$6, Lookup_Performance!$D$2:$D$6, 0,-1) -> 0.02 | X3: =DATEDIF(Q3, TODAY(), "y") & " years " & DATEDIF(Q3, TODAY(), "ym") & "months" -> 10 years 5months
A4: EMP139 | B4: John | C4: Martinez | D4: FIN03 | E4: 103831 | F4: 70 | G4: active | L4: =TRIM(A4) -> EMP139 | M4: =TRIM(PROPER(B4)) -> John | N4: =TRIM(PROPER(C4)) -> Martinez | O4: John Martinez | P4: =TRIM(UPPER(D4)) -> FIN03 | Q4: 44992 | R4: 70 | S4: 103831 | T4: =TRIM(PROPER(G4)) -> Active | U4: =_xlfn.XLOOKUP(P4, Lookup_Departments!$A$2:$A$7, Lookup_Departments!$B$2:$B$7, "invalid code") -> Finance | V4: =_xlfn.XLOOKUP(R4, Lookup_Performance!$A$2:$A$6, Lookup_Performance!$C$2:$C$6, "not found", -1) -> Achieving | W4: =_xlfn.XLOOKUP(R4, Lookup_Performance!$A$2:$A$6, Lookup_Performance!$D$2:$D$6, 0,-1) -> 0.05 | X4: =DATEDIF(Q4, TODAY(), "y") & " years " & DATEDIF(Q4, TODAY(), "ym") & "months" -> 3 years 3months
A5: EMP112 | B5: Thomas | C5: Smith | D5: IT02 | E5: 73785 | F5: 40 | G5: Left | L5: =TRIM(A5) -> EMP112 | M5: =TRIM(PROPER(B5)) -> Thomas | N5: =TRIM(PROPER(C5)) -> Smith | O5: Thomas Smith | P5: =TRIM(UPPER(D5)) -> IT02 | Q5: 44977 | R5: 40 | S5: 73785 | T5: =TRIM(PROPER(G5)) -> Left | U5: =_xlfn.XLOOKUP(P5, Lookup_Departments!$A$2:$A$7, Lookup_Departments!$B$2:$B$7, "invalid code") -> Information Technology | V5: =_xlfn.XLOOKUP(R5, Lookup_Performance!$A$2:$A$6, Lookup_Performance!$C$2:$C$6, "not found", -1) -> Needs Improvement | W5: =_xlfn.XLOOKUP(R5, Lookup_Performance!$A$2:$A$6, Lookup_Performance!$D$2:$D$6, 0,-1) -> 0 | X5: =DATEDIF(Q5, TODAY(), "y") & " years " & DATEDIF(Q5, TODAY(), "ym") & "months" -> 3 years 4months
A6: EMP030 | B6: Emily | C6: Johnson | D6: OPS06 | E6: 115882 | F6: 49 | G6: ACTIVE | L6: =TRIM(A6) -> EMP030 | M6: =TRIM(PROPER(B6)) -> Emily | N6: =TRIM(PROPER(C6)) -> Johnson | O6: Emily Johnson | P6: =TRIM(UPPER(D6)) -> OPS06 | Q6: 43892 | R6: 49 | S6: 115882 | T6: =TRIM(PROPER(G6)) -> Active | U6: =_xlfn.XLOOKUP(P6, Lookup_Departments!$A$2:$A$7, Lookup_Departments!$B$2:$B$7, "invalid code") -> Operations | V6: =_xlfn.XLOOKUP(R6, Lookup_Performance!$A$2:$A$6, Lookup_Performance!$C$2:$C$6, "not found", -1) -> Needs Improvement | W6: =_xlfn.XLOOKUP(R6, Lookup_Performance!$A$2:$A$6, Lookup_Performance!$D$2:$D$6, 0,-1) -> 0 | X6: =DATEDIF(Q6, TODAY(), "y") & " years " & DATEDIF(Q6, TODAY(), "ym") & "months" -> 6 years 4months
A7: EMP096 | B7: John | C7: Wilson | D7: OPS06 | E7: 59980 | F7: 70 | G7: Left | L7: =TRIM(A7) -> EMP096 | M7: =TRIM(PROPER(B7)) -> John | N7: =TRIM(PROPER(C7)) -> Wilson | O7: John Wilson | P7: =TRIM(UPPER(D7)) -> OPS06 | Q7: 45272 | R7: 70 | S7: 59980 | T7: =TRIM(PROPER(G7)) -> Left | U7: =_xlfn.XLOOKUP(P7, Lookup_Departments!$A$2:$A$7, Lookup_Departments!$B$2:$B$7, "invalid code") -> Operations | V7: =_xlfn.XLOOKUP(R7, Lookup_Performance!$A$2:$A$6, Lookup_Performance!$C$2:$C$6, "not found", -1) -> Achieving | W7: =_xlfn.XLOOKUP(R7, Lookup_Performance!$A$2:$A$6, Lookup_Performance!$D$2:$D$6, 0,-1) -> 0.05 | X7: =DATEDIF(Q7, TODAY(), "y") & " years " & DATEDIF(Q7, TODAY(), "ym") & "months" -> 2 years 6months
A8: EMP098 | B8: Jessica | C8: Smith | D8: OPS06 | E8: 68728 | F8: 45 | G8: ACTIVE | L8: =TRIM(A8) -> EMP098 | M8: =TRIM(PROPER(B8)) -> Jessica | N8: =TRIM(PROPER(C8)) -> Smith | O8: Jessica Smith | P8: =TRIM(UPPER(D8)) -> OPS06 | Q8: 44086 | R8: 45 | S8: 68728 | T8: =TRIM(PROPER(G8)) -> Active | U8: =_xlfn.XLOOKUP(P8, Lookup_Departments!$A$2:$A$7, Lookup_Departments!$B$2:$B$7, "invalid code") -> Operations | V8: =_xlfn.XLOOKUP(R8, Lookup_Performance!$A$2:$A$6, Lookup_Performance!$C$2:$C$6, "not found", -1) -> Needs Improvement | W8: =_xlfn.XLOOKUP(R8, Lookup_Performance!$A$2:$A$6, Lookup_Performance!$D$2:$D$6, 0,-1) -> 0 | X8: =DATEDIF(Q8, TODAY(), "y") & " years " & DATEDIF(Q8, TODAY(), "ym") & "months" -> 5 years 9months
A9: EMP140 | B9: Michael | C9: Martinez | D9: SAL05 | E9: 94998 | F9: 58 | G9: Active | L9: =TRIM(A9) -> EMP140 | M9: =TRIM(PROPER(B9)) -> Michael | N9: =TRIM(PROPER(C9)) -> Martinez | O9: Michael Martinez | P9: =TRIM(UPPER(D9)) -> SAL05 | Q9: 42411 | R9: 58 | S9: 94998 | T9: =TRIM(PROPER(G9)) -> Active | U9: =_xlfn.XLOOKUP(P9, Lookup_Departments!$A$2:$A$7, Lookup_Departments!$B$2:$B$7, "invalid code") -> Sales | V9: =_xlfn.XLOOKUP(R9, Lookup_Performance!$A$2:$A$6, Lookup_Performance!$C$2:$C$6, "not found", -1) -> Developing | W9: =_xlfn.XLOOKUP(R9, Lookup_Performance!$A$2:$A$6, Lookup_Performance!$D$2:$D$6, 0,-1) -> 0.02 | X9: =DATEDIF(Q9, TODAY(), "y") & " years " & DATEDIF(Q9, TODAY(), "ym") & "months" -> 10 years 4months
A10: EMP020 | B10: Emily | C10: Miller | D10: sal05 | E10: 118635 | F10: 49 | G10: Active | L10: =TRIM(A10) -> EMP020 | M10: =TRIM(PROPER(B10)) -> Emily | N10: =TRIM(PROPER(C10)) -> Miller | O10: Emily Miller | P10: =TRIM(UPPER(D10)) -> SAL05 | Q10: 43911 | R10: 49 | S10: 118635 | T10: =TRIM(PROPER(G10)) -> Active | U10: =_xlfn.XLOOKUP(P10, Lookup_Departments!$A$2:$A$7, Lookup_Departments!$B$2:$B$7, "invalid code") -> Sales | V10: =_xlfn.XLOOKUP(R10, Lookup_Performance!$A$2:$A$6, Lookup_Performance!$C$2:$C$6, "not found", -1) -> Needs Improvement | W10: =_xlfn.XLOOKUP(R10, Lookup_Performance!$A$2:$A$6, Lookup_Performance!$D$2:$D$6, 0,-1) -> 0 | X10: =DATEDIF(Q10, TODAY(), "y") & " years " & DATEDIF(Q10, TODAY(), "ym") & "months" -> 6 years 3months
A11: EMP057 | B11: Emily | C11: Hernandez | D11: IT02 | E11: 76918 | F11: 62 | G11: Active | L11: =TRIM(A11) -> EMP057 | M11: =TRIM(PROPER(B11)) -> Emily | N11: =TRIM(PROPER(C11)) -> Hernandez | O11: Emily Hernandez | P11: =TRIM(UPPER(D11)) -> IT02 | Q11: 42425 | R11: 62 | S11: 76918 | T11: =TRIM(PROPER(G11)) -> Active | U11: =_xlfn.XLOOKUP(P11, Lookup_Departments!$A$2:$A$7, Lookup_Departments!$B$2:$B$7, "invalid code") -> Information Technology | V11: =_xlfn.XLOOKUP(R11, Lookup_Performance!$A$2:$A$6, Lookup_Performance!$C$2:$C$6, "not found", -1) -> Developing | W11: =_xlfn.XLOOKUP(R11, Lookup_Performance!$A$2:$A$6, Lookup_Performance!$D$2:$D$6, 0,-1) -> 0.02 | X11: =DATEDIF(Q11, TODAY(), "y") & " years " & DATEDIF(Q11, TODAY(), "ym") & "months" -> 10 years 4months
A12: EMP016 | B12: Jane | C12: Williams | D12: mkt04 | E12: 61408 | F12: 48 | G12: ACTIVE | L12: =TRIM(A12) -> EMP016 | M12: =TRIM(PROPER(B12)) -> Jane | N12: =TRIM(PROPER(C12)) -> Williams | O12: Jane Williams | P12: =TRIM(UPPER(D12)) -> MKT04 | Q12: 44364 | R12: 48 | S12: 61408 | T12: =TRIM(PROPER(G12)) -> Active | U12: =_xlfn.XLOOKUP(P12, Lookup_Departments!$A$2:$A$7, Lookup_Departments!$B$2:$B$7, "invalid code") -> Marketing | V12: =_xlfn.XLOOKUP(R12, Lookup_Performance!$A$2:$A$6, Lookup_Performance!$C$2:$C$6, "not found", -1) -> Needs Improvement | W12: =_xlfn.XLOOKUP(R12, Lookup_Performance!$A$2:$A$6, Lookup_Performance!$D$2:$D$6, 0,-1) -> 0 | X12: =DATEDIF(Q12, TODAY(), "y") & " years " & DATEDIF(Q12, TODAY(), "ym") & "months" -> 5 years 0months
A13: EMP070 | B13: Jane | C13: Miller | D13: MKT04 | E13: 99990 | F13: 54 | G13: Active | L13: =TRIM(A13) -> EMP070 | M13: =TRIM(PROPER(B13)) -> Jane | N13: =TRIM(PROPER(C13)) -> Miller | O13: Jane Miller | P13: =TRIM(UPPER(D13)) -> MKT04 | Q13: 44001 | R13: 54 | S13: 99990 | T13: =TRIM(PROPER(G13)) -> Active | U13: =_xlfn.XLOOKUP(P13, Lookup_Departments!$A$2:$A$7, Lookup_Departments!$B$2:$B$7, "invalid code") -> Marketing | V13: =_xlfn.XLOOKUP(R13, Lookup_Performance!$A$2:$A$6, Lookup_Performance!$C$2:$C$6, "not found", -1) -> Developing | W13: =_xlfn.XLOOKUP(R13, Lookup_Performance!$A$2:$A$6, Lookup_Performance!$D$2:$D$6, 0,-1) -> 0.02 | X13: =DATEDIF(Q13, TODAY(), "y") & " years " & DATEDIF(Q13, TODAY(), "ym") & "months" -> 6 years 0months
... A118: EMP103 | B118: Amanda | C118: Brown | D118: IT02 | E118: 118634 | F118: 91 | G118: ACTIVE | L118: =TRIM(A118) -> EMP103 | M118: =TRIM(PROPER(B118)) -> Amanda | N118: =TRIM(PROPER(C118)) -> Brown | O118: Amanda Brown | P118: =TRIM(UPPER(D118)) -> IT02 | Q118: 44848 | R118: 91 | S118: 118634 | T118: =TRIM(PROPER(G118)) -> Active | U118: =_xlfn.XLOOKUP(P118, Lookup_Departments!$A$2:$A$7, Lookup_Departments!$B$2:$B$7, "invalid code") -> Information Technology | V118: =_xlfn.XLOOKUP(R118, Lookup_Performance!$A$2:$A$6, Lookup_Performance!$C$2:$C$6, "not found", -1) -> Exceeding | W118: =_xlfn.XLOOKUP(R118, Lookup_Performance!$A$2:$A$6, Lookup_Performance!$D$2:$D$6, 0,-1) -> 0.08 | X118: =DATEDIF(Q118, TODAY(), "y") & " years " & DATEDIF(Q118, TODAY(), "ym") & "months" -> 3 years 8months

Sheet Raw_Employee_Data
A1: Emp ID | B1: First_Name | C1: Last_Name | D1: Dept Code | E1: Hire Date | F1: Salary | G1: Perf_Score | H1: Employment Status
A2: EMP127 | B2: Emily | C2: Brown | D2: IT02 | E2: 43093 | F2: 50361 | G2: 52 | H2: active
A3: EMP046 | B3: Richard | C3: Hernandez | D3: MKT04 | E3: 44659 | F3: 112673 | H3: ACTIVE
A4: EMP134 | B4: Emily | C4: Gonzalez | D4: IT02 | E4: 42431 | F4: $114,425 | G4: 54 | H4: LEFT
A5: EMP139 | B5: John | C5: Martinez | D5: FIN03 | E5: 45110 | F5: 103831 | G5: 70 | H5: active
A6: EMP112 | B6: Thomas | C6: Smith | D6: IT02 | E6: 44977 | F6: 73785 | G6: 40 | H6: Left
A7: EMP030 | B7: Emily | C7: Johnson | D7: OPS06 | E7: 02-Mar-20 | F7: 115882 | G7: 49 | H7: ACTIVE
A8: EMP096 | B8: John | C8: Wilson | D8: OPS06 | E8: 45272 | F8: 59980 | G8: 70 | H8: Left
A9: EMP098 | B9: Jessica | C9: Smith | D9: OPS06 | E9: 44174 | F9: 68728 | G9: 45 | H9: ACTIVE
A10: EMP095 | C10: Rodriguez | D10: FIN03 | E10: 43107 | F10: 102139 | G10: 79 | H10: active
A11: EMP140 | B11: Michael | C11: Martinez | D11: SAL05 | E11: 42676 | F11: 94998 | G11: 58 | H11: Active
A12: EMP020 | B12: Emily | C12: Miller | D12: sal05 | E12: 43911 | F12: $118,635 | G12: 49 | H12: Active
A13: EMP057 | B13: Emily | C13: Hernandez | D13: IT02 | E13: 42425 | F13: 76918 | G13: 62 | H13: Actv
A14: EMP016 | B14: Jane | C14: Williams | D14: mkt04 | E14: 17-Jun-21 | F14: 61408 | G14: 48 | H14: ACTIVE
A15: EMP070 | B15: Jane | C15: Miller | D15: MKT04 | E15: 44001 | F15: 99990 | G15: 54 | H15: Actv
A16: EMP025 | B16: Robert | C16: Jones | D16: MKT04 | E16: 43820 | F16: 80385 | H16: active
A17: EMP031 | B17: Thomas | C17: Rodriguez | D17: SAL05 | E17: 45169 | F17: 65290 | G17: 77 | H17: active
A18: EMP126 | B18: Emily | C18: Davis | D18: IT02 | E18: 42337 | F18: 105765 | G18: 42 | H18: Active
A19: EMP109 | B19: James | C19: Martinez | D19: SAL05 | E19: 42899 | F19: 102921 | G19: 49 | H19: ACTIVE
A20: EMP057 | B20: Emily | C20: Hernandez | D20: IT02 | E20: 42425 | F20: 76918 | G20: 62 | H20: Actv
A21: EMP066 | B21: Ashley | C21: Lopez | D21: MKT04 | E21: 43235 | F21: 73984 | G21: 93 | H21: Actv
A22: EMP120 | B22: Amanda | C22: Gonzalez | D22: IT02 | E22: 42575 | G22: 75 | H22: Actv
A23: EMP019 | B23: Michael | C23: Hernandez | D23: FIN03 | E23: 43076 | F23: 118527 | G23: 50 | H23: Actv
A24: EMP013 | B24: Richard | C24: Hernandez | D24: MKT04 | E24: 44353 | F24: 107871 | G24: 88 | H24: active
A25: EMP010 | B25: Michael | C25: Rodriguez | D25: IT02 | E25: 44815 | F25: 93956 | G25: 50 | H25: LEFT
A26: EMP032 | B26: Jessica | C26: Johnson | D26: FIN03 | E26: 42565 | F26: 100851 | G26: 64 | H26: ACTIVE
A27: EMP082 | B27: Ashley | C27: Williams | D27: SAL05 | E27: 44728 | F27: 68655 | G27: 32 | H27: active
A28: EMP052 | C28: Williams | D28: SAL05 | E28: 45134 | F28: 81205 | G28: 59 | H28: Actv
A29: EMP129 | B29: John | C29: Wilson | D29: SAL05 | E29: 09/24/2019 | F29: $77,610 | G29: 88 | H29: Actv
A30: EMP146 | B30: Thomas | C30: Rodriguez | D30: it02 | E30: 44765 | F30: $50,873 | G30: 90 | H30: Active
A31: EMP099 | B31: Michael | C31: Wilson | D31: fin03 | E31: 13-May-18 | F31: 85312 | G31: 66 | H31: active
A32: EMP015 | B32: John | C32: Rodriguez | D32: SAL05 | E32: 42202 | G32: 68 | H32: active
A33: EMP076 | B33: Thomas | C33: Hernandez | D33: OPS06 | E33: 05-Aug-15 | F33: 97055 | G33: 80 | H33: Actv
A34: EMP137 | B34: Michael | C34: Johnson | D34: IT02 | E34: 45195 | F34: 66069 | G34: 72 | H34: Actv
A35: EMP056 | B35: Sarah | C35: Brown | D35: it02 | E35: 10-Jun-19 | F35: 90157 | G35: 58 | H35: active
A36: EMP125 | B36: Jane | C36: Martinez | D36: HR01 | E36: 44578 | F36: 59899 | G36: 78 | H36: Actv
A37: EMP085 | B37: Emily | C37: Jones | D37: FIN03 | E37: 03-Jul-17 | F37: 113389 | G37: 30 | H37: ACTIVE
A38: EMP106 | C38: Brown | D38: IT02 | E38: 01-Sep-15 | F38: 102691 | G38: 52 | H38: Active
A39: EMP043 | B39: John | C39: Wilson | D39: OPS06 | E39: 03-Aug-22 | F39: 111845 | G39: 98 | H39: active
A40: EMP068 | B40: Melissa | C40: Brown | D40: SAL05 | E40: 06/29/2022 | F40: 69219 | G40: 93 | H40: Actv
...

Sheet Lookup_Departments
A1: Dept_Code | B1: Department_Name
A2: HR01 | B2: Human Resources
A3: IT02 | B3: Information Technology
A4: FIN03 | B4: Finance
A5: MKT04 | B5: Marketing
A6: SAL05 | B6: Sales
A7: OPS06 | B7: Operations

Sheet Lookup_Performance
A1: Min_Score | B1: Max_Score | C1: Performance_Band | D1: Bonus_Percentage
A2: 0 | B2: 49 | C2: Needs Improvement | D2: 0
A3: 50 | B3: 69 | C3: Developing | D3: 0.02
A4: 70 | B4: 84 | C4: Achieving | D4: 0.05
A5: 85 | B5: 94 | C5: Exceeding | D5: 0.08
A6: 95 | B6: 100 | C6: Outstanding | D6: 0.12
